#!/usr/bin/env python3
"""
Simple verification script for TrackioConfig update fix
"""

try:
    import trackio
    print("‚úÖ Trackio imported successfully")
    
    # Test config access
    config = trackio.config
    print(f"‚úÖ Config accessed: {type(config)}")
    
    # Test update method exists
    print(f"‚úÖ Update method exists: {hasattr(config, 'update')}")
    
    # Test update with keyword arguments (TRL style)
    config.update(allow_val_change=True, test_attr='test_value')
    print(f"‚úÖ Update with kwargs worked: allow_val_change={config.allow_val_change}, test_attr={config.test_attr}")
    
    # Test update with dictionary
    config.update({'project_name': 'test_project', 'new_attr': 'dict_value'})
    print(f"‚úÖ Update with dict worked: project_name={config.project_name}, new_attr={config.new_attr}")
    
    # Test TRL functions
    print(f"‚úÖ Init function exists: {hasattr(trackio, 'init')}")
    print(f"‚úÖ Log function exists: {hasattr(trackio, 'log')}")
    print(f"‚úÖ Finish function exists: {hasattr(trackio, 'finish')}")
    
    print("\nüéâ All tests passed! The fix is working correctly.")
    
except Exception as e:
    print(f"‚ùå Test failed: {e}")
    import traceback
    traceback.print_exc() 